Workbook

Sheet WBD BS
B2: Mina Vista Capital Management
B4: WBD_balance-sheet_Annual_As_Originally_Reported | C4: 2024 | D4: 2023 | E4: 2022 | F4: 2021 | G4: 2020
B5: Total Assets | C5: 104560 | D5: 122757 | E5: 134001 | F5: 34427 | G5: 34087
B6: Total Current Assets | C6: 14078 | D6: 14218 | E6: 13999 | F6: 7264 | G6: 6130
B7: Cash, Cash Equivalents and Short Term Investments | C7: 5312 | D7: 3780 | E7: 3731 | F7: 3905 | G7: 2091
B8: Cash and Cash Equivalents | C8: 5312 | D8: 3780 | E8: 3731 | F8: 3905 | G8: 2091
B9: Trade and Other Receivables, Current | C9: 5926 | D9: 7312 | E9: 7611 | F9: 2446 | G9: 2537
B10: Trade/Accounts Receivable, Current | C10: 4947 | D10: 6047 | E10: 6380 | F10: 2446 | G10: 2537
B11: Gross Trade/Accounts Receivable, Current | F11: 2500
B12: Allowance/Adjustments for Trade/Accounts Receivable, Current | F12: -54
B13: Other Receivables, Current | C13: 979 | D13: 1265 | E13: 1231
B14: Prepayments and Deposits, Current | C14: 784 | D14: 843
B15: Other Current Assets | C15: 2056 | D15: 2283 | E15: 2657 | F15: 913 | G15: 1502
B16: Deferred Tax Assets, Current
B17: Total Non-Current Assets | C17: 90482 | D17: 108539 | E17: 120002 | F17: 27163 | G17: 27957
B18: Net Property, Plant and Equipment | C18: 6087 | D18: 5957 | E18: 5301 | F18: 1336 | G18: 1206
B19: Gross Property, Plant and Equipment | C19: 10122 | D19: 9042 | E19: 7356 | F19: 2665 | G19: 2569
B20: Properties | C20: 3832 | D20: 4013 | E20: 3251 | F20: 481 | G20: 334
B21: Machinery, Furniture and Equipment | C21: 5689 | D21: 4685 | E21: 3537 | F21: 1371 | G21: 1491
B22: Furniture, Fixtures and Office Equipment | C22: 5689 | D22: 4685 | E22: 3537 | F22: 1371 | G22: 1491
B23: Construction in Progress and Advance Payments | C23: 601 | D23: 344 | E23: 568 | F23: 141
B24: Other Property, Plant and Equipment | F24: 672 | G24: 744
B25: Accumulated Depreciation and Impairment | C25: -4035 | D25: -3085 | E25: -2055 | F25: -1329 | G25: -1363
B26: Accumulated Depreciation | C26: -4035 | D26: -3085 | E26: -2055 | F26: -1329 | G26: -1363
B27: Net Intangible Assets | C27: 77068 | D27: 94483 | E27: 106072 | F27: 23061 | G27: 24149
B28: Gross Goodwill and Other Intangible Assets | C28: 112125 | D28: 114554 | E28: 119165 | F28: 30069 | G28: 28393
B29: Goodwill | C29: 36467 | D29: 36569 | E29: 36038 | F29: 14532 | G29: 13070
B30: Intangibles other than Goodwill | C30: 75658 | D30: 77985 | E30: 83127 | F30: 15537 | G30: 15323
B31: Trademarks and Patents | C31: 22835 | D31: 22935 | E31: 22876 | F31: 1877 | G31: 1912
B32: Licenses and Rights | C32: 27997 | D32: 30124 | E32: 35547 | F32: 3832 | G32: 3439
B33: Customer Relationships | C33: 24240 | D33: 24335 | E33: 24136 | F33: 9433 | G33: 9551
B34: Other Intangible Assets | C34: 586 | D34: 591 | E34: 568 | F34: 395 | G34: 421
B35: Accumulated Amortization and Impairment | C35: -35057 | D35: -20071 | E35: -13093 | F35: -7008 | G35: -4244
B36: Accumulated Amortization of Intangible Assets | C36: -24257 | D36: -18471 | E36: -11493 | F36: -5388 | G36: -4244
... B38: Accumulated Amortization of Trademarks and Patents | C38: -4212 | D38: -2688 | E38: -1494 | F38: -858 | G38: -715
B39: Accumulated Amortization of Licences and Rights | C39: -986 | D39: -551 | E39: -217
B40: Accumulated Amortization of Customer Relationships | C40: -18528 | D40: -14730 | E40: -9458 | F40: -4303 | G40: -3338
B41: Accumulated Amortization of Other Intangible Assets | C41: -531 | D41: -502 | E41: -324 | F41: -227 | G41: -191
B42: Accumulated Impairment of Intangible Assets | C42: -10800 | D42: -1600 | E42: -1600 | F42: -1620
B43: Accumulated Impairment of Goodwill | C43: -10800 | D43: -1600 | E43: -1600 | F43: -1620
...

Sheet WBD CFS
B2: Mina Vista Capital Management
B4: WBD_cash-flow_Annual_As_Originally_Reported | C4: 2020 | D4: 2021 | E4: 2022 | F4: 2023 | G4: 2024 | H4: TTM
B5: Cash Flow from Operating Activities, Indirect | C5: 2739000000 | D5: 2798000000 | E5: 4304000000 | F5: 7477000000 | G5: 5375000000 | H5: 5230000000
B6: Net Cash Flow from Continuing Operating Activities, Indirect | C6: 2739000000 | D6: 2798000000 | E6: 4304000000 | F6: 7477000000 | G6: 5375000000 | H6: 5230000000
B7: Cash Generated from Operating Activities | C7: 2739000000 | D7: 2798000000 | E7: 4304000000 | F7: 7477000000 | G7: 5375000000 | H7: 5230000000
B8: Income/Loss before Non-Cash Adjustment | C8: 1355000000 | D8: 1197000000 | E8: -7297000000 | F8: -3079000000 | G8: -11482000000 | H8: 356000000
B9: Total Adjustments for Non-Cash Items | C9: 4483000000 | D9: 4838000000 | E9: 22583000000 | F9: 22545000000 | G9: 28983000000 | H9: 15725000000
B10: Depreciation, Amortization and Depletion, Non-Cash Adjustment | C10: 4315000000 | D10: 5083000000 | E10: 21354000000 | F10: 24009000000 | G10: 20983000000 | H10: 18172000000
B11: Depreciation and Amortization, Non-Cash Adjustment | C11: 4315000000 | D11: 5083000000 | E11: 21354000000 | F11: 24009000000 | G11: 20983000000 | H11: 18172000000
B12: Depreciation, Non-Cash Adjustment | C12: 1359000000 | D12: 1582000000 | E12: 7193000000 | F12: 7985000000 | G12: 7037000000 | H12: 6012000000
B13: Amortization, Non-Cash Adjustment | C13: 2956000000 | D13: 3501000000 | E13: 14161000000 | F13: 16024000000 | G13: 13946000000 | H13: 12160000000
B14: Stock-Based Compensation, Non-Cash Adjustment | C14: 110000000 | D14: 178000000 | E14: 412000000 | F14: 500000000 | G14: 557000000 | H14: 678000000
B15: Deferred Taxes, Non-Cash Adjustment | C15: -186000000 | D15: -511000000 | E15: -2842000000 | F15: -2344000000 | G15: -1732000000 | H15: -653000000
B16: Net Investment Income/Loss, Non-Cash Adjustment | C16: 28000000 | D16: 44000000 | E16: -489000000 | F16: 6000000 | G16: -76000000 | H16: 61000000
B17: Realized Gain/Loss on Disposal/Sale of Financial Instruments, Non-Cash Adjustment | C17: -103000000 | D17: -19000000 | E17: -199000000 | F17: 0 | G17: -227000000 | H17: -27000000
B18: Gain/Loss on Derivatives, Non-Cash Adjustment | C18: -36000000 | E18: -501000000 | F18: -151000000 | G18: -16000000
B19: Share of Profit/Loss from Associates, Joint Ventures and other Equity Investments, Non-Cash Adjustment | C19: 167000000 | D19: 63000000 | E19: 211000000 | F19: 157000000 | G19: 167000000 | H19: 63000000
B20: Irregular Income/Loss, Non-Cash Adjustment | C20: 202000000 | D20: -61000000 | E20: 2924000000 | F20: 115000000 | G20: 9136000000 | H20: -2477000000
B21: Write Down and Write off of Other Assets, Non-Cash Adjustment | F21: 0 | G21: 9603000000 | H21: 353000000
B22: Gain/Loss on Extinguishment of Debt, Non-Cash Adjustment | C22: 76000000 | D22: 10000000 | E22: 0 | G22: -632000000 | H22: -2995000000
B23: Reorganization and M&A, Non-Cash Adjustment | E23: 2808000000 | F23: 115000000 | G23: 165000000
B24: Gain/Loss on Disposals, Non-Cash Adjustment | C24: 2000000 | D24: -71000000 | E24: 116000000
B25: Gain/Loss on Disposal/Sale of Fixed Assets, Non-Cash Adjustment | E25: 116000000
B26: Gain/Loss on Disposal/Sale of Business, Non-Cash Adjustment | C26: 2000000
B27: Impairment of Goodwill, Non-Cash Adjustment | C27: 124000000 | D27: 0
B28: Other Non-Cash Items | C28: 14000000 | D28: 105000000 | E28: 1224000000 | F28: 259000000 | G28: 115000000 | H28: -56000000
B29: Changes in Operating Capital | C29: -3099000000 | D29: -3237000000 | E29: -10982000000 | F29: -11989000000 | G29: -12126000000 | H29: -10851000000
B30: Change in Trade and Other Receivables | C30: 105000000 | D30: 47000000 | E30: 181000000 | F30: 312000000 | G30: 1012000000 | H30: 295000000
B31: Change in Trade/Accounts Receivable
B32: Change in Tax Receivables
B33: Change in Payables and Accrued Expenses | C33: -131000000 | D33: 185000000 | E33: -12562000000 | F33: -13125000000 | G33: -12878000000 | H33: -11787000000
B34: Change in Trade and Other Payables | C34: -131000000 | D34: 185000000 | E34: -12562000000 | F34: -13125000000 | G34: -12878000000 | H34: -11787000000
B35: Change in Trade/Accounts Payable | C35: -131000000 | D35: 185000000 | F35: -820000000 | G35: -529000000 | H35: 562000000
B36: Change in Other Payables | E36: -12562000000 | F36: -12305000000 | G36: -12349000000
B37: Change in Other Operating Capital | C37: -3073000000 | D37: -3469000000 | E37: 1399000000 | F37: 824000000 | G37: -260000000 | H37: 641000000
B38: Change in Other Current Liabilities
B39: Cash Flow from Investing Activities | C39: -703000000 | D39: -56000000 | E39: 3524000000 | F39: -1259000000 | G39: -349000000 | H39: -755000000
B40: Cash Flow from Continuing Investing Activities | C40: -703000000 | D40: -56000000 | E40: 3524000000 | F40: -1259000000 | G40: -349000000 | H40: -755000000
B41: Purchase/Sale and Disposal of Property, Plant and Equipment, Net | C41: -402000000 | D41: -373000000 | E41: -987000000 | F41: -1316000000 | G41: -948000000 | H41: -1096000000
B42: Purchase of Property, Plant and Equipment | C42: -402000000 | D42: -373000000 | E42: -987000000 | F42: -1316000000 | G42: -948000000 | H42: -1096000000
...

Sheet NFLX CFS
B2: Mina Vista Capital Management
B4: NFLX_cash-flow_Annual_As_Originally_Reported | C4: 2020 | D4: 2021 | E4: 2022 | F4: 2023 | G4: 2024 | H4: TTM
B5: Cash Flow from Operating Activities, Indirect | C5: 2427077000 | D5: 392610000 | E5: 2026257000 | F5: 7274301000 | G5: 7361364000 | H5: 9574525000
B6: Net Cash Flow from Continuing Operating Activities, Indirect | C6: 2427077000 | D6: 392610000 | E6: 2026257000 | F6: 7274301000 | G6: 7361364000 | H6: 9574525000
B7: Cash Generated from Operating Activities | C7: 14206361000 | D7: 18094812000 | E7: 18865295000 | F7: 7274301000 | G7: 7361364000 | H7: -2219690000
B8: Income/Loss before Non-Cash Adjustment | C8: 2761395000 | D8: 5116228000 | E8: 4491924000 | F8: 5407990000 | G8: 8711631000 | H8: 10431287000
B9: Total Adjustments for Non-Cash Items | C9: 11476839000 | D9: 13220561000 | E9: 15131458000 | F9: 1982459000 | G9: -1317192000 | H9: -12376658000
B10: Depreciation, Amortization and Depletion, Non-Cash Adjustment | C10: 10922622000 | D10: 12438779000 | E10: 14362814000 | F10: 14554384000 | G10: 15630431000 | H10: 16146376000
B11: Depreciation and Amortization, Non-Cash Adjustment | C11: 10922622000 | D11: 12438779000 | E11: 14362814000 | F11: 14554384000 | G11: 15630431000 | H11: 16146376000
B12: Depreciation, Non-Cash Adjustment | C12: 115710000 | D12: 208412000 | E12: 336682000 | F12: 356947000 | G12: 328914000 | H12: 326945000
B13: Amortization, Non-Cash Adjustment | C13: 10806912000 | D13: 12230367000 | E13: 14026132000 | F13: 14197437000 | G13: 15301517000 | H13: 15819431000
B14: Stock-Based Compensation, Non-Cash Adjustment | C14: 415180000 | D14: 403220000 | E14: 575452000 | F14: 339368000 | G14: 272588000 | H14: 295652000
B15: Deferred Taxes, Non-Cash Adjustment | C15: 70066000 | D15: 199548000 | E15: -166550000 | F15: -459359000 | G15: -590698000 | H15: -352396000
B16: Net Investment Income/Loss, Non-Cash Adjustment | C16: 533278000 | D16: -430661000 | E16: -353111000 | F16: 176296000 | G16: -121539000 | H16: 29223000
... B18: Other Non-Cash Items | C18: -464307000 | D18: 609675000 | E18: 712853000 | F18: -12628230000 | G18: -16507974000 | H18: -28495513000
B19: Excess Tax Benefit from Stock-Based Compensation, Non-Cash Adjustment
B20: Irregular Income/Loss, Non-Cash Adjustment
B21: Gain/Loss on Extinguishment of Debt, Non-Cash Adjustment
B22: Changes in Operating Capital | C22: -31873000 | D22: -241977000 | E22: -758087000 | F22: -116148000 | G22: -33075000 | H22: -274319000
B23: Change in Other Current Assets | C23: -187623000 | D23: -369681000 | E23: -353834000 | F23: -181003000 | G23: 22180000 | H23: -519513000
B24: Change in Payables and Accrued Expenses | C24: 156578000 | D24: 325453000 | E24: -214056000 | F24: 197067000 | G24: 313252000 | H24: 751188000
B25: Change in Trade and Other Payables | C25: -41605000 | D25: 145115000 | E25: -158543000 | F25: 93502000 | G25: 121353000 | H25: 129450000
B26: Change in Trade/Accounts Payable | C26: -41605000 | D26: 145115000 | E26: -158543000 | F26: 93502000 | G26: 121353000 | H26: 129450000
B27: Change in Accrued Expenses | C27: 198183000 | D27: 180338000 | E27: -55513000 | F27: 103565000 | G27: 191899000 | H27: 621738000
B28: Change in Deferred Assets/Liabilities | C28: 193247000 | D28: 91350000 | E28: 27356000 | F28: 178708000 | G28: 77844000 | H28: 211627000
B29: Change in Other Operating Capital | C29: -194075000 | D29: -289099000 | E29: -217553000 | F29: -310920000 | G29: -446351000 | H29: -717621000
B30: Other Operating Cash Flow | C30: -11779284000 | D30: -17702202000 | E30: -16839038000
B31: Cash Flow from Investing Activities | C31: -505354000 | D31: -1339853000 | E31: -2076392000 | F31: 541751000 | G31: -2181784000 | H31: 1139543000
B32: Cash Flow from Continuing Investing Activities | C32: -505354000 | D32: -1339853000 | E32: -2076392000 | F32: 541751000 | G32: -2181784000 | H32: 1139543000
B33: Purchase/Sale and Disposal of Property, Plant and Equipment, Net | C33: -497923000 | D33: -524585000 | E33: -407729000 | F33: -348552000 | G33: -439538000 | H33: -607559000
B34: Purchase of Property, Plant and Equipment | C34: -497923000 | D34: -524585000 | E34: -407729000 | F34: -348552000 | G34: -439538000 | H34: -607559000
B35: Purchase/Sale of Business, Net | D35: -788349000 | E35: -757387000 | F35: 0 | G35: 0
B36: Purchase/Acquisition of Business | D36: -788349000 | E36: -757387000 | F36: 0 | G36: 0
B37: Purchase/Sale of Investments, Net | E37: -911276000 | F37: 890303000 | G37: -1742246000 | H37: 1747102000
B38: Purchase of Investments | E38: -911276000 | F38: -504862000 | G38: -1742246000 | H38: -161515000
B39: Sale of Investments | F39: 1395165000 | G39: 0 | H39: 1908617000
B40: Purchase/Sale of Other Non-Current Assets, Net | C40: -7431000 | D40: -26919000 | E40: 0 | F40: 0
B41: Purchase/Sale of Intangibles, Net
B42: Purchase of Intangibles
B43: Cash Flow from Financing Activities | C43: 1237311000 | D43: -1149776000 | E43: -664254000 | F43: -5950803000 | G43: -4074427000 | H43: -8946911000
...

Sheet WBD IS
B2: Mina Vista Capital Management
B4: WBD_income-statement_Annual_As_Originally_Reported | C4: TTM | D4: 2024 | E4: 2023 | F4: 2022 | G4: 2021 | H4: 2020
B5: Gross Profit | C5: 16674 | D5: 16351 | E5: 16795 | F5: 13375 | G5: 7571 | H5: 6811
B6: Total Revenue | C6: 37863 | D6: 39321 | E6: 41321 | F6: 33817 | G6: 12191 | H6: 10671
B7: Business Revenue | C7: 36718 | D7: 38088 | E7: 40140 | F7: 33026 | G7: 11624 | H7: 10449
B8: Other Revenue | C8: 1145 | D8: 1233 | E8: 1181 | F8: 791 | G8: 567 | H8: 222
B9: Cost of Revenue | C9: -21189 | D9: -22970 | E9: -24526 | F9: -20442 | G9: -4620 | H9: -3860
B10: Operating Income/Expenses | C10: -15262 | D10: -16333 | E10: -17681 | F10: -16871 | G10: -5598 | H10: -4081
B11: Selling, General and Administrative Expenses | C11: -9250 | D11: -9296 | E11: -9696 | F11: -9678 | G11: -4016 | H11: -2722
B12: Depreciation, Amortization and Depletion | C12: -6012 | D12: -7037 | E12: -7985 | F12: -7193 | G12: -1582 | H12: -1359
B13: Depreciation and Amortization | C13: -6012 | D13: -7037 | E13: -7985 | F13: -7193 | G13: -1582 | H13: -1359
B14: Total Operating Profit/Loss | C14: 1412 | D14: 18 | E14: -886 | F14: -3496 | G14: 1973 | H14: 2730
B15: Non-Operating Income/Expense, Total | C15: 279 | D15: -11406 | E15: -2977 | F15: -5464 | G15: -540 | H15: -1002
B16: Total Net Finance Income/Expense | C16: -1783 | D16: -1807 | E16: -2042 | F16: -1777 | G16: -615 | H16: -638
... B18: Interest Expense Net of Capitalized Interest | C18: -1991 | D18: -2017 | E18: -2221 | F18: -1777 | G18: -633 | H18: -648
B19: Interest Income | C19: 208 | D19: 210 | E19: 179 | G19: 18 | H19: 10
B20: Net Investment Income | C20: -28 | D20: -465 | E20: -263 | F20: -82 | G20: 38 | H20: -62
B21: Fair Value or Unrealized Gain/Loss on Financial Assets | C21: 26 | D21: -12 | E21: -36 | F21: -247 | G21: -19 | H21: 28
B22: Income from Associates, JointVentures and Other Participating Interests | C22: -17 | D22: -121 | E22: -82 | F22: -160 | G22: -18 | H22: -105
B23: Shareof Profit and Interest from Joint Venture | E23: -82 | F23: -160
B24: Income from Other Participating Interests | G24: -18 | H24: -105
B25: Gain/Loss on Foreign Currency Exchange | C25: -95 | D25: -323 | E25: -173 | F25: -150 | G25: 93 | H25: -115
B26: Gain/Loss on Derivatives | C26: 58 | D26: -9 | E26: 28 | F26: 475 | G26: -33 | H26: 29
B27: Gain/Loss on Investments and Other Financial Instruments | E27: 0 | F27: 0 | G27: 15 | H27: 101
B28: Irregular Income/Expense | C28: 2057 | D28: -9147 | E28: -645 | F28: -3679 | G28: 29 | H28: -300
B29: Disposal of Businesses | C29: -9 | D29: 194 | E29: 0 | F29: 195 | G29: 71 | H29: 2
B30: Impairment/Write Off/Write Down of Capital Assets | C30: -353 | D30: -9603 | E30: -77 | F30: -117
B31: Gain/Loss on Extinguishment of Debt | C31: 2995 | D31: 632 | G31: -10 | H31: -76
B32: Restructuring and Reorganization Income/Expense | C32: -508 | D32: -447 | E32: -585 | F32: -3757 | G32: -32 | H32: -91
B33: Other Irregular Income/Expense | C33: -68 | D33: 77
B34: Debt Restructuring | E34: 17 | F34: 0 | G34: 0 | H34: -11
B35: Goodwill Impairment/Write Off | G35: 0 | H35: -124
B36: Write Off/Write Down of Other Assets
B37: Other Income/Expense, Non-Operating | C37: 33 | D37: 13 | E37: -27 | F37: 74 | G37: 8 | H37: -2
B38: Pretax Income | C38: 1691 | D38: -11388 | E38: -3863 | F38: -8960 | G38: 1433 | H38: 1728
B39: Provision for Income Tax | C39: -1335 | D39: -94 | E39: 784 | F39: 1663 | G39: -236 | H39: -373
B40: Net Income before Extraordinary Items and Discontinued Operations | C40: 356 | D40: -11482 | E40: -3079 | F40: -7297 | G40: 1197 | H40: 1355
B41: Net Income after Extraordinary Items and Discontinued Operations | C41: 356 | D41: -11482 | E41: -3079 | F41: -7297 | G41: 1197 | H41: 1355
B42: Non-Controlling/Minority Interests | C42: 129 | D42: 171 | E42: -47 | F42: -74 | G42: -191 | H42: -136
B43: Net Income after Non-Controlling/Minority Interests | C43: 485 | D43: -11311 | E43: -3126 | F43: -7371 | G43: 1006 | H43: 1219
...

Sheet NFLX IS
B2: Mina Vista Capital Management
B4: NFLX_income-statement_Annual_As_Originally_Reported | C4: TTM | D4: 2024 | E4: 2023 | F4: 2022 | G4: 2021 | H4: 2020
B5: Gross Profit | C5: 20858.715 | D5: 17962.502 | E5: 14007.929 | F5: 12447.265 | G5: 12365.161 | H5: 9719.737
B6: Total Revenue | C6: 43378.787 | D6: 39000.966 | E6: 33723.297 | F6: 31615.55 | G6: 29697.844 | H6: 24996.056
B7: Business Revenue | C7: 43378.787 | D7: 39000.966 | E7: 33723.297 | F7: 31615.55 | G7: 29697.844 | H7: 24996.056
B8: Cost of Revenue | C8: -22520.072 | D8: -21038.464 | E8: -19715.368 | F8: -19168.285 | G8: -17332.683 | H8: -15276.319
B9: Operating Income/Expenses | C9: -8216.009 | D9: -7544.888 | E9: -7053.926 | F9: -6814.434 | G9: -6170.652 | H9: -5134.448
B10: Selling, General and Administrative Expenses | C10: -4938.414 | D10: -4619.593 | E10: -4378.168 | F10: -4103.393 | G10: -3896.767 | H10: -3304.848
B11: General and Administrative Expenses | C11: -1774.28 | D11: -1702.039 | E11: -1720.285 | F11: -1572.891 | G11: -1351.621 | H11: -1076.486
B12: Selling and Marketing Expenses | C12: -3164.134 | D12: -2917.554 | E12: -2657.883 | F12: -2530.502 | G12: -2545.146 | H12: -2228.362
B13: Research and Development Expenses | C13: -3277.595 | D13: -2925.295 | E13: -2675.758 | F13: -2711.041 | G13: -2273.885 | H13: -1829.6
B14: Total Operating Profit/Loss | C14: 12642.706 | D14: 10417.614 | E14: 6954.003 | F14: 5632.831 | G14: 6194.509 | H14: 4585.289
B15: Non-Operating Income/Expense, Total | C15: -553.627 | D15: -451.957 | E15: -748.598 | F15: -368.902 | G15: -354.406 | H15: -1385.94
B16: Total Net Finance Income/Expense | C16: -553.627 | D16: -451.957 | E16: -748.598 | F16: -368.902 | G16: -354.406 | H16: -1385.94
... B18: Interest Expense Net of Capitalized Interest | C18: -734.718 | D18: -718.733 | E18: -748.598 | F18: -706.212 | G18: -765.62 | H18: -1385.94
B19: Interest Income | C19: 181.091 | D19: 266.776 | F19: 337.31 | G19: 411.214
B20: Irregular Income/Expense
B21: Gain/Loss on Extinguishment of Debt
B22: Pretax Income | C22: 12089.079 | D22: 9965.657 | E22: 6205.405 | F22: 5263.929 | G22: 5840.103 | H22: 3199.349
B23: Provision for Income Tax | C23: -1657.792 | D23: -1254.026 | E23: -797.415 | F23: -772.005 | G23: -723.875 | H23: -437.954
B24: Net Income before Extraordinary Items and Discontinued Operations | C24: 10431.287 | D24: 8711.631 | E24: 5407.99 | F24: 4491.924 | G24: 5116.228 | H24: 2761.395
B25: Net Income after Extraordinary Items and Discontinued Operations | C25: 10431.287 | D25: 8711.631 | E25: 5407.99 | F25: 4491.924 | G25: 5116.228 | H25: 2761.395
B26: Net Income after Non-Controlling/Minority Interests | C26: 10431.287 | D26: 8711.631 | E26: 5407.99 | F26: 4491.924 | G26: 5116.228 | H26: 2761.395
B27: Net Income Available to Common Stockholders | C27: 10431.287 | D27: 8711.631 | E27: 5407.99 | F27: 4491.924 | G27: 5116.228 | H27: 2761.395
B28: Diluted Net Income Available to Common Stockholders | C28: 10431.287 | D28: 8711.631 | E28: 5407.99 | F28: 4491.924 | G28: 5116.228 | H28: 2761.395
B29: Income Statement Supplemental Section
B30: Reported Normalized and Operating Income/Expense Supplemental Section
B31: Total Revenue as Reported, Supplemental | C31: 43378.787 | D31: 39000.966 | E31: 33723.297 | F31: 31615.55 | G31: 29697.844 | H31: 24996.056
B32: Reported Total Operating Profit/Loss | C32: 12642.706 | D32: 10417.614 | E32: 6954.003 | F32: 5632.831 | G32: 6194.509 | H32: 4585.289
B33: Reported Effective Tax Rate | D33: 0.13 | E33: 0.13 | F33: 0.15 | G33: 0.12 | H33: 0.14
B34: Reported Normalized EBITDA | F34: 6544.965
B35: Dilution to Earnings
B36: Basic EPS | C36: 2.45 | D36: 2.03 | E36: 1.23 | F36: 1.01 | G36: 1.16 | H36: 0.63
B37: Diluted EPS | C37: 2.39 | D37: 1.98 | E37: 1.2 | F37: 0.99 | G37: 1.12 | H37: 0.61
B38: Basic WASO | C38: 4261.515 | D38: 4295.19 | E38: 4415.71 | F38: 4446.98 | G38: 4431.55 | H38: 4409.22
B39: Diluted WASO | C39: 4359.0625 | D39: 4392.61 | E39: 4494.98 | F39: 4512.9 | G39: 4553.72 | H39: 4542.08
B40: Fiscal year ends in Dec 31 | USD

Sheet Segment Info 
B2: Mina Vista Capital Management
B4: Networks Segment (Not Part of the deal) | C4: 2024 | D4: 2023 | E4: % Change | F4: % Change (ex-FX) | H4: Studios Segment | I4: 2024 | J4: 2023 | K4: % Change | L4: % Change (ex-FX) | N4: DTC Segment | O4: 2024 | P4: 2023 | Q4: % Change | R4: % Change (ex-FX) | T4: DTC + Studios | U4: 2024 | V4: 2023
B5: Revenues: | H5: Revenue: | N5: Revenues: | T5: =N5 -> Revenues:
B6: Distribution | C6: 10680 | D6: 11521 | E6: -0.07 | F6: -0.06 | H6: Distribution | I6: 8 | J6: 17 | K6: -0.53 | L6: -0.53 | N6: Distribution | O6: 9022 | P6: 8703 | Q6: 0.04 | R6: 0.05 | T6: =N6 -> Distribution | U6: =O6 -> 9022 | V6: =P6 -> 8703
B7: Advertising | C7: 7306 | D7: 8342 | E7: -0.12 | F7: -0.12 | H7: Advertising | I7: 5 | J7: 15 | K7: -0.67 | L7: -0.67 | N7: Advertising | O7: 855 | P7: 548 | Q7: 0.56 | R7: 0.57 | T7: =N7 -> Advertising | U7: =O7 -> 855 | V7: =P7 -> 548
B8: Content | C8: 1848 | D8: 1005 | E8: 0.84 | F8: 0.83 | H8: Content | I8: 10717 | J8: 11358 | K8: -0.06 | L8: -0.05 | N8: Content | O8: 428 | P8: 886 | Q8: -0.52 | R8: -0.51 | T8: =N8 -> Content | U8: =O8 -> 428 | V8: =P8 -> 886
B9: Other | C9: 341 | D9: 376 | E9: -0.09 | F9: -0.1 | H9: Other | I9: 877 | J9: 802 | K9: 0.09 | L9: 0.09 | N9: Other | O9: 8 | P9: 17 | Q9: -0.53 | R9: -0.5 | T9: =N9 -> Other | U9: =O9 -> 8 | V9: =P9 -> 17
B10: Total revenues | C10: 20175 | D10: 21244 | E10: -0.05 | F10: -0.04 | H10: **Total revenues** | I10: 11607 | J10: 12192 | K10: -0.05 | L10: -0.05 | N10: Total revenues | O10: 10313 | P10: 10154 | Q10: 0.02 | R10: 0.02 | T10: DTC Segment Total | U10: =O10 -> 10313 | V10: =P10 -> 10154
B11: Costs of revenues, excluding depreciation and amortization | C11: 9238 | D11: 9342 | E11: -0.01 | F11: — % | H11: Costs of revenues, excluding depreciation and amortization | I11: 7530 | J11: 7296 | K11: 0.03 | L11: 0.03 | N11: Costs of revenues, excluding depreciation and amortization | O11: 7459 | P11: 7623 | Q11: -0.02 | R11: -0.02 | T11: Studios Segment
B12: Selling, general and administrative | C12: 2788 | D12: 2839 | E12: -0.02 | F12: -0.01 | H12: Selling, general and administrative | I12: 2425 | J12: 2713 | K12: -0.11 | L12: -0.11 | N12: Selling, general and administrative | O12: 2177 | P12: 2428 | Q12: -0.1 | R12: -0.09 | T12: =H6 -> Distribution | U12: =I6 -> 8 | V12: =J6 -> 17
B13: Adjusted EBITDA | C13: 8149 | D13: 9063 | E13: -0.1 | F13: -0.1 | H13: **Adjusted EBITDA** | I13: 1652 | J13: 2183 | K13: -0.24 | L13: -0.23 | N13: Adjusted EBITDA | O13: 677 | P13: 103 | Q13: NM | R13: NM | T13: =H7 -> Advertising | U13: =I7 -> 5 | V13: =J7 -> 15
B14: Depreciation and amortization | C14: 4172 | D14: 4961 | H14: Depreciation and amortization | I14: 702 | J14: 667 | N14: Depreciation and amortization | O14: 1831 | P14: 2063 | T14: =H8 -> Content | U14: =I8 -> 10717 | V14: =J8 -> 11358
B15: Restructuring and other charges | C15: 85 | D15: 201 | H15: Employee share-based compensation | I15: -1 | J15: – | N15: Restructuring and other charges | O15: 3 | P15: 66 | T15: =H9 -> Other | U15: =I9 -> 877 | V15: =J9 -> 802
B16: Transaction and integration costs | C16: 2 | D16: 3 | H16: Restructuring and other charges | I16: 263 | J16: 225 | N16: Transaction and integration costs | O16: -1 | P16: 4 | T16: Studios Segment Revenues | U16: =I10 -> 11607 | V16: =J10 -> 12192
B17: Impairment and amortization of fair value step-up for content | C17: 495 | D17: 473 | H17: Transaction and integration costs | I17: 2 | J17: 7 | N17: Impairment and amortization of fair value step-up for content | O17: 282 | P17: 460
B18: Inter-segment eliminations | C18: — | D18: 90 | H18: Facility consolidation costs | I18: 1 | J18: – | N18: Inter-segment eliminations | O18: — | P18: 72 | T18: Total Revenue | U18: =U16+U10 -> 21920 | V18: =V16+V10 -> 22346
B19: Impairments and loss on dispositions | C19: 9154 | D19: 13 | H19: Impairment and amortization of fair value step-up for content | I19: 96 | J19: 995 | N19: Impairments and loss on dispositions | O19: 47 | P19: 3 | T19: =N11 -> Costs of revenues, excluding depreciation and amortization | U19: =O11+I11 -> 14989 | V19: =P11+J11 -> 14919
B20: Operating (loss) income | C20: -5759 | D20: 3322 | H20: Amortization of capitalized interest for content | I20: 46 | J20: 46 | N20: Operating loss | O20: -1485 | P20: -2565 | T20: =N12 -> Selling, general and administrative | U20: =O12+I12 -> 4602 | V20: =P12+J12 -> 5141
H21: Inter-segment eliminations | I21: – | J21: 31
H22: Impairments and loss on dispositions | I22: 14 | J22: 1 | T22: =N13 -> Adjusted EBITDA | U22: =U18-U19-U20 -> 2329 | V22: =V18-V19-V20 -> 2286
H23: **Operating income** | I23: 529 | J23: 211 | T23: =N14 -> Depreciation and amortization | U23: =O14+I14 -> 2533 | V23: =P14+J14 -> 2730
T24: =N15 -> Restructuring and other charges | U24: =O15+I16 -> 266 | V24: =P15+J16 -> 291
T25: =N16 -> Transaction and integration costs | U25: =O16+I17 -> 1 | V25: =P16+J17 -> 11
T26: =N17 -> Impairment and amortization of fair value step-up for content | U26: =O17+I19 -> 378 | V26: =P17+J19 -> 1455
T27: =H20 -> Amortization of capitalized interest for content | U27: =I20 -> 46 | V27: =J20 -> 46
T28: =N18 -> Inter-segment eliminations | U28: =I21 -> – | V28: =P18+J21 -> 103
T29: =N19 -> Impairments and loss on dispositions | U29: =O19+I22 -> 61 | V29: =P19+J22 -> 4
T30: Operating Income | U30: =U22-SUM(U23:U29) -> -956 | V30: =V22-SUM(V23:V29) -> -2354

Sheet IS Analysis 
B2: Mina Vista Capital Management
B3: SCENARIO SELECT: | C3: 2
B5: Division | C5: Approx Post Merger | D5: Approx 2024 Revenue | E5: % of Studios Revenue | F5: Value | G5: Justification
B6: Television product | C6: =(_xlfn.XLOOKUP(F6,$D$14:$D$18,$E$14:$E$18))*D6 -> 6760 | D6: 5200 | E6: ~45–48% | F6: 4 | G6: I see synergystic value to licencing and the production of shows but no use of its live studio arm.
B7: Film/Theatrical + Home Ent | C7: =(_xlfn.XLOOKUP(F7,$D$14:$D$18,$E$14:$E$18))*D7 -> 2050 | D7: 4100 | E7: ~35–38% | F7: 2 | G7: I do not see synergystic value to its theatrical releases and expect Netflix to eventually leave that space. I also see its home enertainment arm being dismantled.
B8: Games | C8: =(_xlfn.XLOOKUP(F8,$D$14:$D$18,$E$14:$E$18))*D8 -> 1560 | D8: 1200 | E8: ~7–10% | F8: 4 | G8: I see videogame studios being used by Netflix to crete original games even though revenue for this division decreased 53%
B9: Other | C9: =(_xlfn.XLOOKUP(F9,$D$14:$D$18,$E$14:$E$18))*D9 -> 110 | D9: 1100 | E9: 0.08 | F9: 1 | G9: WBD's theme parks will be a hassle to dismantle
B10: Content Total | C10: =SUM(C6:C9) -> 10480 | D10: 11600 | F10: =C10/D10*3 -> 2.7103448
D13: Synergystic values | E13: Multiple | F13: We assigned a value from 1-5 to each of the divisions. 1 means a dismantling of the division, 3 means Netflix will likely use it but we see no synergistic value and 5 means synergistic value meaning it will have a higher revenue. | J13: DTC Segment | K13: After merger | L13: 2024 | M13: 2023 | O13: Income Statement | P13: NTFX + WBD | Q13: NTFX | R13: WBD
D14: 1 | E14: =CHOOSE($C$3,D33,E33,F33) -> 0.1 | J14: Revenues: | P14: After Merger | Q14: Before merger
D15: 2 | E15: =CHOOSE($C$3,D34,E34,F34) -> 0.5 | J15: Distribution | L15: 9022 | M15: 8703 | O15: Total Revenue | P15: =Q15+R15 -> 70359.587 | Q15: ='NFLX IS'!C6 -> 43378.787 | R15: =K28 -> 26980.8
D16: 3 | E16: =CHOOSE($C$3,D35,E35,F35) -> 1 | J16: Advertising | L16: 855 | M16: 548 | O16: ='NFLX IS'!B8 -> Cost of Revenue | P16: =Q16+R16 -> -36759.622 | Q16: ='NFLX IS'!C8 -> -22520.072 | R16: =-K29 -> -14239.55
D17: 4 | E17: =CHOOSE($C$3,D36,E36,F36) -> 1.3 | J17: Content | L17: 428 | M17: 886 | O17: Gross Revenue | P17: =P15+P16 -> 33599.965 | Q17: =Q15+Q16 -> 20858.715
D18: 5 | E18: =CHOOSE($C$3,D37,E37,F37) -> 1.6 | J18: Other | L18: 8 | M18: 17 | O18: ='NFLX IS'!B10 -> Selling, General and Administrative Expenses | P18: =Q18+R18 -> -9080.214 | Q18: ='NFLX IS'!C10 -> -4938.414 | R18: =-K31 -> -4141.8 | U18: Interest Expense Calculation | V18: WBD
J19: DTC Segment Total | K19: =L19*(E18) -> 16500.8 | L19: =SUM(L15:L18) -> 10313 | M19: =SUM(M15:M18) -> 10154 | O19: ='NFLX IS'!B13 -> Research and Development Expenses | P19: =Q19+R19 -> -3277.595 | Q19: ='NFLX IS'!C13 -> -3277.595 | V19: cost of debt
B20: GROWTH ASSUMPTIONS | K20: (Synergystic value of 5) | O20: ='WBD IS'!B12 -> Depreciation, Amortization and Depletion | P20: =Q20+R20 -> -2279.7 | R20: =-K35 -> -2279.7 | U20: Debt | V20: =33521 -> 33521
B21: Item | D21: Growth % | E21: Notes | J21: Studios Segment | O21: Other operating expenses | P21: =Q21+R21 -> -671.87 | R21: =-SUM(K37:K45) -> -671.87 | U21: Interest expense | V21: =-R24 -> 1991
B22: Cost of Revenue | D22: =CHOOSE($C$3,D40,E40,F40) -> -0.05 | E22: YoY change | J22: Distribution | L22: 8 | M22: 17 | O22: ='WBD IS'!B14 -> Total Operating Profit/Loss | P22: =SUM(P17:P21) -> 18290.586 | Q22: =SUM(Q17:Q21) -> 12642.706 | R22: =SUM(R15:R21) -> 5647.88 | U22: Cost Of Debt | V22: =V21/V20 -> 0.059395603
B23: SG&A | D23: =CHOOSE($C$3,D41,E41,F41) -> -0.1 | E23: YoY change | J23: Advertising | L23: 5 | M23: 15 | S23: How I will calculate how much is attributed to the Studio and DTC segments
B24: Depreciation & Amortization | D24: =CHOOSE($C$3,D42,E42,F42) -> -0.1 | E24: YoY change | J24: Content | L24: 10717 | M24: 11358 | O24: ='NFLX IS'!B18 -> Interest Expense Net of Capitalized Interest | P24: =-V42+Q24 -> -5072.2509 | Q24: ='NFLX IS'!C18 -> -734.718 | R24: ='WBD IS'!C18 -> -1991 | S24: I assumed WBD's cost of debt on the acquired debt amount (10.7B)plus the additional debt on the new 50B of debt incurred by Netflix using Netflix's cost of debt | V24: NTFX
B25: Restructuring & Other Charges | D25: =CHOOSE($C$3,D43,E43,F43) -> -0.1 | E25: YoY change | J25: Other | L25: 877 | M25: 802 | O25: ='NFLX IS'!B19 -> Interest Income | P25: =Q25 -> 181.091 | Q25: ='NFLX IS'!C19 -> 181.091 | R25: ='WBD IS'!C19 -> 208 | S25: 0 because it is not acquring cash | V25: Cast of debt
B26: Impairment of Content | D26: =CHOOSE($C$3,D44,E44,F44) -> -0.11 | E26: YoY change | J26: Studios Segment Revenues | K26: =C10 -> 10480 | L26: =SUM(L22:L25) -> 11607 | M26: =SUM(M22:M25) -> 12192 | U26: Debt | V26: 17083
B27: Amort of Capitalized Interest | D27: =CHOOSE($C$3,D45,E45,F45) -> -0.12 | E27: YoY change | O27: ='WBD IS'!B20 -> Net Investment Income | P27: 0 | R27: ='WBD IS'!C20 -> -28 | S27: 0 because it is based on cash | U27: Interest Expense | V27: =-'IS Analysis '!Q24 -> 734.718
B28: Impairments & Loss on Dispositions | D28: =CHOOSE($C$3,D46,E46,F46) -> -0.1 | E28: YoY change | J28: Total Revenue | K28: =SUM(K26,K19) -> 26980.8 | L28: =SUM(L26,L19) -> 21920 | M28: =SUM(M26,M19) -> 22346 | O28: ='WBD IS'!B28 -> Irregular Income/Expense | P28: =R28*S42 -> 530.41995 | R28: ='WBD IS'!C28 -> 2057 | S28: Ebitda share | U28: Interest on Debt Schedule | V28: 0.06
J29: Costs of revenues, excluding depreciation and amortization | K29: =L29*(1+K30) -> 14239.55 | L29: 14989 | M29: 14919 | O29: ='WBD IS'!B37 -> Other Income/Expense, Non-Operating | P29: =R29*S42 -> 8.509411 | R29: ='WBD IS'!C37 -> 33 | S29: Ebitda share | U29: Cost Of Debt | V29: =V27/V26 -> 0.043008722
J30: Growth % | K30: =$D$22 -> -0.05 | L30: =L29/M29-1 -> 0.0046920035 | O30: ='WBD IS'!B15 -> Non-Operating Income/Expense, Total | P30: =SUM(P24:P29) -> -4352.2306 | Q30: =SUM(Q24:Q25) -> -553.627 | R30: =SUM(R24:R29) -> 279
B31: SCENARIO TABLES | J31: Selling, general and administrative | K31: =L31*(1+K32) -> 4141.8 | L31: 4602 | M31: 5141
B32: Synergistic Multiples | D32: Conservative | E32: Normal | F32: Optimistic | J32: Growth % | K32: =$D$23 -> -0.1 | L32: =L31/M31-1 -> -0.10484342 | U32: NFLX after merger debt calculation
B33: Value 1 (Dismantle) | D33: 0.05 | E33: 0.1 | F33: 0.2 | O33: ='WBD IS'!B39 -> Provision for Income Tax | P33: =P45 -> -1717.5872 | Q33: ='NFLX IS'!C23 -> -1657.792 | R33: ='WBD IS'!C39 -> -1335 | S33: use the 1691 M of pre tax income, then weigh it based on EBITDA and then assume Netflix's tax rate | U33: NTFX cost of debt | V33: =V28 -> 0.06
B34: Value 2 (Divest) | D34: 0.3 | E34: 0.5 | F34: 0.7 | J34: Adjusted EBITDA | K34: =K28-(K29+K31) -> 8599.45 | L34: 2329 | M34: 2286 | O34: ='WBD IS'!B42 -> Non-Controlling/Minority Interests | P34: 0 | R34: ='WBD IS'!C42 -> 129 | S34: 0 because it is insuficient | U34: WBD Cost of Debt | V34: =V22 -> 0.059395603
B35: Value 3 (No Synergy) | D35: 0.9 | E35: 1 | F35: 1.1 | J35: Depreciation and amortization | K35: =L35*(1+K36) -> 2279.7 | L35: 2533 | M35: 2730 | O35: ='WBD IS'!B47 -> Other Adjustments to Net Income Available to Common Stockholders | P35: 0 | R35: ='WBD IS'!C47 -> -3 | S35: 0 because it is insuficient
B36: Value 4 (Moderate Synergy) | D36: 1.1 | E36: 1.3 | F36: 1.5 | K36: =$D$24 -> -0.1 | O36: Net Income | P36: =P22+(SUM(P30,P33)) -> 12220.768 | Q36: =Q22+(SUM(Q30,Q33)) -> 10431.287 | R36: ='WBD IS'!C48 -> 482 | U36: Acquired Debt | V36: 10700
B37: Value 5 (High Synergy) | D37: 1.3 | E37: 1.6 | F37: 2 | J37: Restructuring and other charges | K37: =L37*(1+K38) -> 239.4 | L37: 266 | M37: 291 | U37: Acquired debt Interest expense | V37: =V36*V34 -> 635.53295
K38: =$D$25 -> -0.1 | O38: Studio tax | R38: Total EBITDA share
B39: Growth Assumptions | D39: Conservative | E39: Normal | F39: Optimistic | J39: Transaction and integration costs | K39: =L39 -> 1 | L39: 1 | M39: 11 | O39: WBD Pre tax income | P39: ='WBD IS'!C38 -> 1691 | R39: Studio EBITDA | S39: 1652 | U39: Acquisition Debt | V39: 61700
B40: Cost of Revenue | D40: -0.02 | E40: -0.05 | F40: -0.08 | J40: Impairment and amortization of fair value step-up for content | K40: =L40*(1+K41) -> 336.42 | L40: 378 | M40: 1455 | O40: Studio + DTC Share | P40: =S42 -> 0.25786094 | R40: DTC EBITDA | S40: 677 | U40: Interest Expense on Acquisition Debt | V40: =V39*V33 -> 3702
B41: SG&A | D41: -0.05 | E41: -0.1 | F41: -0.15 | K41: =$D$26 -> -0.11 | O41: weighted WBD Pre tax income | P41: =P39*P40 -> 436.04285 | R41: Total EBITDA | S41: 9032
B42: Depreciation & Amortization | D42: -0.05 | E42: -0.1 | F42: -0.15 | J42: Amortization of capitalized interest for content | K42: =L42*(1+K43) -> 40.48 | L42: 46 | M42: 46 | O42: Netflix Pre Tax | P42: ='NFLX IS'!C22 -> 12089.079 | R42: Studio + DTC share | S42: =(S39+S40)/S41 -> 0.25786094 | U42: Interest Expense | V42: =V37+V40 -> 4337.5329
B43: Restructuring & Other | D43: -0.05 | E43: -0.1 | F43: -0.2 | K43: =$D$27 -> -0.12 | O43: Total pretax | P43: =SUM(P41:P42) -> 12525.122
B44: Impairment of Content | D44: -0.05 | E44: -0.11 | F44: -0.2 | J44: Inter-segment eliminations | M44: 103 | O44: Tax rate | P44: =-'NFLX IS'!C23/'NFLX IS'!C22 -> 0.13713137
...

Sheet BS Analysis 
B2: Mina Vista Capital Management
B4: Balance Sheet Analysis | D4: 45901 | E4: 45809 | F4: 45717 | H4: Asset | I4: Details/Value | J4: Value | L4: Liability item (what shows up on pro forma BS) | M4: Where it comes from | N4: WBD consolidated amount (Sep 30, 2025) | O4: Rough amount Netflix assumes for “Streaming & Studios” (≈53.2%) | P4: Notes
C5: After the merger | D5: Before the merger
B6: Cash & Short Term Investments | H6: Content Library | I6: $21.2 B capitalized film, TV & game content (net) – vast back catalog of films and series (e.g. Harry Potter, LoTR, Friends) | J6: 21200 | L6: Acquisition debt | M6: New Netflix borrowing | N6: — | O6: 61700 | P6: All-cash deal: $61.7B new debt raised (orig $50B + $11.7B shifted from equity). No equity issued.
B7: Cash and Equivalents | C7: 0 | D7: 9287.3 | E7: 8177.4 | F7: 7199.8 | H7: Intellectual Property | I7: $38.3 B intangible assets (net) – includes franchises, characters, trade names (HBO, WB, DC, etc.) valued at ~$21 B | J7: 38300 | L7: Net debt assumed (Studios & Streaming) | M7: Assumed with acquired business | N7: — | O7: 10700 | P7: Deck explicitly shows Studios & Streaming net debt. (Not the same as taking all WBD gross debt.)
B8: Short Term Investments | C8: 0 | D8: 37.1 | E8: 213.1 | F8: 1171.1 | H8: Goodwill | I8: $33.0 B goodwill – adjusted from $35.0B to balance pro forma BS (purchase price allocation residual) | J8: 33008.9 | L8: Accounts payable | M8: Assumed operating liability | N8: 1083 | O8: 577 | P8: From WBD balance sheet category.
B9: Total Cash & ST Investments | C9: =D9-10300 -> -975.6 | D9: 9324.4 | E9: 8390.5 | F9: 8371 | H9: Subscriber Base | I9: ~97.7 M DTC subscribers (2023); grew to 110.5 M in Q3 2024 – HBO/Max and Discovery+ paying users | J9: 0 | L9: Accrued liabilities | M9: Assumed operating liability | N9: 9292 | O9: 4947 | P9: From WBD balance sheet category.
B10: Receivables | C10: =D10 -> 0 | H10: Studio Facilities & Tech | I10: ~$6.0 B in property & equipment – Hollywood studio lots, production facilities, and streaming tech infrastructure | J10: 6000 | L10: Deferred revenues | M10: Assumed operating liability | N10: 1649 | O10: 878 | P10: Includes prepaid subs/contract liabilities.
B11: Accounts Receivable | C11: =D11 -> 1688.8 | D11: 1688.8 | E11: 1579.9 | F11: 1448 | H11: Games & Other Assets | I11: 11 game development studios (WB Games) + licensed game portfolio; consumer product licensing business; studio tours, etc. (contributing ~$0.8 B “Other” revenue in 2023) | J11: 0 | L11: Other noncurrent liabilities | M11: Assumed operating liability | N11: 10961 | O11: 5836 | P11: Catch-all line that can include leases, participations, etc.
B12: Other Receivables | C12: =D12 -> — | D12: — | E12: — | F12: — | I12: Total | J12: =SUM(J6:J11) -> 98508.9 | L12: Deferred income taxes | M12: Potentially assumed/adjusted | N12: 6708 | O12: 3571 | P12: Often heavily reshaped by purchase accounting (DTLs/DTAs get remeasured). Still a “bucket” you may need.
B13: Total Receivables | C13: =D13 -> 1688.8 | D13: 1688.8 | E13: 1579.9 | F13: 1448 | L13: Total incremental liabilities (rough) | O13: =SUM(O6:O12) -> 88209 | P13: Sum of the rows above (rough).
B14: Current Assets | I14: = Asset/Liability Items added
B15: Prepaid Expenses | C15: =D15 -> 467.6 | D15: 467.6 | E15: 451.1 | F15: 484.4
B16: Restricted Cash | C16: =D16 -> — | D16: — | E16: — | F16: —
B17: Other Current Assets | C17: =D17 -> 1482.2 | D17: 1482.2 | E17: 1571.7 | F17: 1394.3
B18: Total Current Assets | C18: =SUM(C13:C17,C9) -> 2663 | D18: 12962.9 | E18: 11993.1 | F18: 11697.6
B19: Long-Term Assets
B21: =H10 -> Studio Facilities & Tech | C21: =J10 -> 6000
B22: NLFX Gross PP&E | C22: =D23 -> 5180.4
B23: Gross Property, Plant & Equipment | C23: =SUM(C21:C22) -> 11180.4 | D23: 5180.4 | E23: 4957.2 | F23: 4715.8
B24: Accumulated Depreciation | C24: =D24 -> -1045.8 | D24: -1045.8 | E24: -1038.3 | F24: -976.2
B25: Net Property, Plant & Equipment | C25: =SUM(C23:C24) -> 10134.6 | D25: 4134.6 | E25: 3918.9 | F25: 3739.6
B26: =H6 -> Content Library | C26: =J6 -> 21200
B27: =H8 -> Goodwill | C27: =J8 -> 33008.9
B28: IP | C28: =J7 -> 38300
B29: NFLX other intangibles | C29: =D30 -> 12182.2
B30: Other Intangibles | C30: =SUM(C26:C29) -> 104691.1 | D30: 12182.2 | E30: 12273.1 | F30: 12393.1
B31: Deferred Tax Assets | D31: — | E31: — | F31: —
B32: Other Long-Term Assets | C32: =D32 -> 25655.1 | D32: 25655.1 | E32: 24914.6 | F32: 24257.3
B33: Total Assets | C33: =SUM(C32,C30,C25,C18) -> 143143.8 | D33: =SUM(D32,D30,D25,D18) -> 54934.8 | E33: =SUM(E32,E30,E25,E18) -> 53099.7 | F33: =SUM(F32,F30,F25,F18) -> 52087.6
B34: Current Liabilities
B35: WBD Accounts payable incured | C35: =O8 -> 577
B36: NFLX Accounts Payable | C36: =D36 -> 793.2 | D36: 793.2 | E36: 632.7 | F36: 614.5
B37: Accrued liabilites Incurred | C37: =O9 -> 4947
B38: Accrued Expenses | C38: =D38 -> 2168.2 | D38: 2168.2 | E38: 1434.4 | F38: 1728.7
B39: =L10 -> Deferred revenues | C39: =O10 -> 878
B40: Current Portion of LT Debt | D40: — | E40: — | F40: 1005.9
B41: Current Portion of Lease Obligations | C41: =D41 -> 457.4 | D41: 457.4 | E41: 453.9 | F41: 437.3
B42: Unearned Revenue, Current | C42: =D42 -> 1724.7 | D42: 1724.7 | E42: 1728.4 | F42: 1609.7
B43: Other Current Liabilities | C43: =D43 -> 4588.4 | D43: 4588.4 | E43: 4692.9 | F43: 4322.4
...

Sheet Ratio Analysis 
B2: Mina Vista Capital Management
B3: Scenario: | C3: {=_xlfn.IFS('IS Analysis '!C3=1,"Conservative",'IS Analysis '!C3=2,"Normal",'IS Analysis '!C3=3,"Optimistic")} -> Normal
B5: Profitability metrics | C5: After merger | D5: Before Merger | F5: Margins | G5: After Merger | H5: Before Merger
B6: net Income | C6: ='IS Analysis '!P36 -> 12220.768 | D6: ='IS Analysis '!Q36 -> 10431.287 | F6: Gross margins | G6: ='IS Analysis '!P17/'IS Analysis '!P15 -> 0.47754636 | H6: ='IS Analysis '!Q17/'IS Analysis '!Q15 -> 0.48085058
B7: Total Assets | C7: ='BS Analysis '!C33 -> 143143.8 | D7: ='BS Analysis '!D33 -> 54934.8 | F7: Operating Margin | G7: ='IS Analysis '!P22/'IS Analysis '!P15 -> 0.25995869 | H7: ='IS Analysis '!Q22/'IS Analysis '!Q15 -> 0.29144904
B8: ROA | C8: =C6/C7 -> 0.085374066 | D8: =D6/D7 -> 0.18988486 | F8: Net Margin | G8: ='IS Analysis '!P36/'IS Analysis '!P15 -> 0.17369016 | H8: ='IS Analysis '!Q36/'IS Analysis '!Q15 -> 0.24046977
B10: Operating Income | C10: ='IS Analysis '!P22 -> 18290.586 | D10: ='IS Analysis '!Q22 -> 12642.706
B11: operating ROA | C11: =C10/C7 -> 0.1277777 | D11: =D10/D7 -> 0.2301402 | F11: Solvency Analysis | G11: =G5 -> After Merger | H11: =H5 -> Before Merger
F12: Debt to Equity
B13: Total Equity | C13: ='BS Analysis '!C62 -> 25954 | D13: ='BS Analysis '!D62 -> 25954 | F13: Past Debt | G13: =H13 -> 17083.5 | H13: ='BS Analysis '!D71 -> 17083.5
B14: ROE | C14: =C6/C13 -> 0.47086261 | D14: =D6/D13 -> 0.40191443 | F14: Incurred Debt | G14: ='BS Analysis '!O6+'BS Analysis '!O7 -> 72400
F15: Total | G15: =G13+G14 -> 89483.5 | H15: =H13+H14 -> 17083.5
F16: Equity | G16: ='BS Analysis '!C62 -> 25954 | H16: ='BS Analysis '!D62 -> 25954
F17: Debt to Equity | G17: =G15/G16 -> 3.447773 | H17: =H15/H16 -> 0.65822224
B18: ROIC Analysis | C18: After Merger | D18: Before Merger | F18: Debt to capital | G18: =G15/(G15+G16) -> 0.77516838 | H18: =H15/(H15+H16) -> 0.39694453
B19: NOPAT Calculation
B20: Operating Income (EBIT) | C20: ='IS Analysis '!P22 -> 18290.586 | D20: ='IS Analysis '!Q22 -> 12642.706 | F20: Financial Leverage
B21: Tax Rate | C21: ='IS Analysis '!P44 -> 0.13713137 | D21: ='IS Analysis '!P44 -> 0.13713137 | F21: Total Assets | G21: ='BS Analysis '!C33 -> 143143.8 | H21: ='BS Analysis '!D33 -> 54934.8
B22: NOPAT | C22: =C20*(1-C21) -> 15782.373 | D22: =D20*(1-D21) -> 10908.994 | F22: (-)Godwill | G22: =-'BS Analysis '!C27 -> -33008.9 | H22: =-'BS Analysis '!D27 -> 0
F23: (-) Defered Revenue | G23: =-'BS Analysis '!C39 -> -878 | H23: =-'BS Analysis '!D39 -> 0
B24: Invested Capital Calculation | F24: Total Interest Bearing Assets | G24: =G21+SUM(G22:G23) -> 109256.9 | H24: =H21+SUM(H22:H23) -> 54934.8
B25: Total Assets | C25: ='BS Analysis '!C33 -> 143143.8 | D25: ='BS Analysis '!D33 -> 54934.8 | F25: Financial Leverage | G25: =G24/G16 -> 4.2096363 | H25: =H24/H16 -> 2.1166217
B26: (-) Cash & ST Investments | C26: =-'BS Analysis '!C9 -> 975.6 | D26: =-'BS Analysis '!D9 -> -9324.4
B27: (-) Accounts Payable | C27: =-('BS Analysis '!C35+'BS Analysis '!C36) -> -1370.2 | D27: =-'BS Analysis '!D36 -> -793.2 | F27: Debt to EBITDA Ratio
B28: (-) Accrued Liabilities | C28: =-('BS Analysis '!C37+'BS Analysis '!C38) -> -7115.2 | D28: =-'BS Analysis '!D38 -> -2168.2 | F28: EBITDA | G28: =('IS Analysis '!P22+'IS Analysis '!$P$20) -> 16010.886 | H28: =('IS Analysis '!Q22+'IS Analysis '!$P$20) -> 10363.006
B29: (-) Deferred Revenue | C29: =-('BS Analysis '!C39+'BS Analysis '!C42) -> -2602.7 | D29: =-('BS Analysis '!D42) -> -1724.7 | F29: Debt to EBITDA Ratio | G29: =G15/G28 -> 5.5889162 | H29: =H15/H28 -> 1.6485082
B30: (-) Other Current Liabilities | C30: =-'BS Analysis '!C43 -> -4588.4 | D30: =-'BS Analysis '!D43 -> -4588.4
B31: (-) Deferred Tax Liability | C31: =-'BS Analysis '!C49 -> -3571 | D31: =-IF(ISNUMBER('BS Analysis '!D50),'BS Analysis '!D50,0) -> 0 | F31: Interest Coverage Ratio
B32: Invested Capital | C32: =SUM(C25:C31) -> 124871.9 | D32: =SUM(D25:D31) -> 36335.9 | F32: EBIT | G32: ='IS Analysis '!P22 -> 18290.586 | H32: ='IS Analysis '!Q22 -> 12642.706
F33: Interest Expense | G33: ='IS Analysis '!P24 -> -5072.2509 | H33: ='IS Analysis '!Q24 -> -734.718
B34: ROIC | C34: =C22/C32 -> 0.12638851 | D34: =D22/D32 -> 0.30022634 | F34: Interest Coverage Ratio | G34: =G32/-G33 -> 3.6060097 | H34: =H32/-H33 -> 17.207563
F36: WACC Analysis | G36: After Merger | H36: Before Merger
F37: Cost of Equity (CAPM)
F38: Risk-Free Rate (10Y UST) | G38: 0.0428 | H38: 0.0428
F39: Equity Risk Premium | G39: 0.0433 | H39: 0.0433
F40: Beta (5Y Monthly) | G40: 1.71 | H40: 1.71
F41: Cost of Equity (Ke) | G41: =G38+G40*G39 -> 0.116843 | H41: =H38+H40*H39 -> 0.116843
F43: Cost of Debt
F44: Pre-Tax Cost of Debt | G44: =-'IS Analysis '!P24/G50 -> 0.056683645 | H44: =-'IS Analysis '!Q24/'BS Analysis '!D71 -> 0.043007463
F45: Tax Rate | G45: ='IS Analysis '!P44 -> 0.13713137 | H45: ='IS Analysis '!P44 -> 0.13713137
...
